<?xml version="1.0" ?>

<!-- | This document was custom generated using the cpp-to-urdf library. For more details visit https://github.com/kmolan/cpp-to-urdf-converter | -->
<!-- | Do not edit this file by hand unless you know what you're doing                                                                          | -->


<robot name="pendulum" xmlns:xacro="http://ros.org/wiki/xacro">
 <material name = "Blue" > 
  <color rgba ="0 0 0.8 1"/>
 </material>

 <material name = "Red" > 
  <color rgba ="1 0 0 1"/>
 </material>

 <material name = "Green" > 
  <color rgba ="0 1 0 1"/>
 </material>

 <link name ="world"> 
  <inertial>
   <origin rpy = "0 0 0" xyz= "0 0 0"/>
   <mass value = "0.01"/>
   <inertia ixx = "0.01" ixy = "0" ixz = "0" iyy = "0" iyz = "0" izz = "0"/>
  </inertial>
 </link>

 <link name ="base_part2"> 
  <inertial>
   <origin rpy = "0 0 0" xyz= "0 0 0.015"/>
   <mass value = "1"/>
   <inertia ixx = "0" ixy = "0" ixz = "0" iyy = "0" iyz = "0" izz = "0"/>
  </inertial>
  <visual>
   <origin rpy = "0 0 0" xyz= "0 0 0.015"/>
   <geometry>
    <sphere radius="0.015"/>
   </geometry>
   <material name = "Green"/>
  </visual>
 </link>

 <joint name = "base_weld" type = "fixed" > 
  <parent link = "world" /> 
  <child link = "base_part2" /> 
   <origin rpy = "0 0 0" xyz= "0 0 1"/>
 </joint> 

 <link name ="arm"> 
  <inertial>
   <origin rpy = "0 0 0" xyz= "0 0 -0.5"/>
   <mass value = "0.5"/>
   <inertia ixx = "0" ixy = "0" ixz = "0" iyy = "0" iyz = "0" izz = "0"/>
  </inertial>
  <visual>
   <origin rpy = "0 0 0" xyz= "0 0 -0.375"/>
   <geometry>
    <cylinder length="0.75" radius = "0.01"/>
   </geometry>
   <material name = "Red"/>
  </visual>
  <collision>
   <origin rpy = "0 0 0" xyz= "0 0 -0.375"/>
   <geometry>
    <cylinder length="0.75" radius = "0.01"/>
   </geometry>
  </collision>
 </link>

 <joint name = "theta" type = "continuous" > 
  <parent link = "base_part2" /> 
  <child link = "arm" /> 
  <axis xyz = "0 1 0" /> 
  <dynamics damping = "0.5" friction = "20"/>
 </joint> 

 <link name ="arm_com"> 
  <inertial>
   <origin rpy = "0 0 0" xyz= "0 0 -0.5"/>
   <mass value = "0.5"/>
   <inertia ixx = "0" ixy = "0" ixz = "0" iyy = "0" iyz = "0" izz = "0"/>
  </inertial>
  <visual>
   <origin rpy = "0 0 0" xyz= "0 0 -0.5"/>
   <geometry>
    <sphere radius="0.025"/>
   </geometry>
   <material name = "Blue"/>
  </visual>
  <collision>
   <origin rpy = "0 0 0" xyz= "0 0 -0.5"/>
   <geometry>
    <sphere radius="0.025"/>
   </geometry>
  </collision>
 </link>

 <joint name = "arm_weld" type = "fixed" > 
  <parent link = "arm" /> 
  <child link = "arm_com" /> 
 </joint> 

 <transmission name = "elbow_trans" type = "SimpleTransmission">
  <actuator name ="tau"/>
  <joint name = "theta"/>
  <mechanicalReduction>1</mechanicalReduction>
 </transmission>

  <gazebo reference = "base_part2">
    <material>Gazebo/Green</material>
  </gazebo>

  <gazebo reference = "arm">
    <material>Gazebo/Red</material>
  </gazebo>

  <gazebo reference = "arm_com">
    <material>Gazebo/Blue</material>
  </gazebo>

</robot>
